Workbook

Sheet Oppsummering
A1: Oppsummering av timelister i prosjekt nr:
A3: Ukenr | B3: Andreas | C3: Brage | D3: Mateusz | E3: Sum timer pr uke | G3: gj. antall timer
A4: 2 | B4: ='Uke 2'!C19 -> 10 | C4: ='Uke 2'!C38 -> 9 | D4: ='Uke 2'!C57 -> 11.5 | E4: =SUM(B4:D4) -> 30.5 | G4: =(D4+C4+B4)/3 -> 10.166667
A5: 3 | B5: ='Uke 3'!C19 -> 13 | C5: ='Uke 3'!C38 -> 10 | D5: ='Uke 3'!C57 -> 15.5 | E5: =SUM(B5:D5) -> 38.5 | G5: =(D5+C5+B5)/3 -> 12.833333
A6: 4 | B6: ='Uke 4'!C19 -> 17.5 | C6: ='Uke 4'!C38 -> 23 | D6: ='Uke 4'!C57 -> 24.5 | E6: =SUM(B6:D6) -> 65 | G6: =(D6+C6+B6)/3 -> 21.666667
A7: 5 | B7: ='Uke 5'!C19 -> 21 | C7: ='Uke 5'!C38 -> 15 | D7: ='Uke 5'!C57 -> 18 | E7: =SUM(B7:D7) -> 54 | G7: =(D7+C7+B7)/3 -> 18
A8: 6 | B8: ='Uke 6'!C19 -> 18 | C8: ='Uke 6'!C38 -> 15.5 | D8: ='Uke 6'!C57 -> 18 | E8: =SUM(B8:D8) -> 51.5 | G8: =(D8+C8+B8)/3 -> 17.166667
A9: 7 | B9: ='Uke 7'!C19 -> 17 | C9: ='Uke 7'!C38 -> 19 | D9: ='Uke 7'!C57 -> 26 | E9: =SUM(B9:D9) -> 62 | G9: =(D9+C9+B9)/3 -> 20.666667
A10: 8 | B10: ='Uke 8'!C19 -> 21 | C10: ='Uke 8'!C38 -> 20 | D10: ='Uke 8'!C57 -> 36 | E10: =SUM(B10:D10) -> 77 | G10: =(D10+C10+B10)/3 -> 25.666667
A11: 9 | B11: ='Uke 9'!C19 -> 20 | C11: ='Uke 9'!C38 -> 17.5 | D11: ='Uke 9'!C57 -> 8.5 | E11: =SUM(B11:D11) -> 46 | G11: =(D11+C11+B11)/3 -> 15.333333
A12: 10 | B12: ='Uke 10'!C19 -> 22 | C12: ='Uke 10'!C38 -> 22.5 | D12: ='Uke 10'!C57 -> 26 | E12: =SUM(B12:D12) -> 70.5 | G12: =(D12+C12+B12)/3 -> 23.5
A13: 11 | B13: ='Uke 11'!C19 -> 6.5 | C13: ='Uke 11'!C38 -> 20.5 | D13: ='Uke 11'!C57 -> 21 | E13: =SUM(B13:D13) -> 48 | G13: =(B13+C13+D13)/3 -> 16
A14: 12 | B14: ='Uke 12'!C19 -> 21 | C14: ='Uke 12'!C38 -> 19.5 | D14: ='Uke 12'!C57 -> 18 | E14: =SUM(B14:D14) -> 58.5 | G14: =(B14+C14+D14)/3 -> 19.5
A15: 13 | B15: ='Uke 13'!C19 -> 16 | C15: ='Uke 13'!C38 -> 23.3 | D15: ='Uke 13'!C57 -> 28.5 | E15: =SUM(B15:D15) -> 67.8 | G15: =(B15+C15+D15)/3 -> 22.6
A16: 14 | B16: ='Uke 14'!C19 -> 0 | C16: ='Uke 14'!C38 -> 0 | D16: ='Uke 14'!C57 -> 9 | E16: =SUM(B16:D16) -> 9 | G16: =(B16+C16+D16)/3 -> 3 | I16: påske
A17: 15 | B17: ='Uke 15'!C19 -> 0.5 | C17: ='Uke 15'!C38 -> 2.5 | D17: ='Uke 15'!C57 -> 1 | E17: =SUM(B17:D17) -> 4 | G17: =(B17+C17+D17)/3 -> 1.3333333
A18: 16 | B18: ='Uke 16'!C19 -> 8 | C18: ='Uke 16'!C38 -> 19 | D18: ='Uke 16'!C57 -> 28 | E18: =SUM(B18:D18) -> 55 | G18: =(B18+C18+D18)/3 -> 18.333333 | I18: INGA eksamen | J18: 16.04
A19: 17 | B19: ='Uke 17'!C19 -> 27.5 | C19: ='Uke 17'!C38 -> 22 | D19: ='Uke 17'!C57 -> 23 | E19: =SUM(B19:D19) -> 72.5 | G19: =(B19+C19+D19)/3 -> 24.166667
A20: 18 | B20: ='Uke 18'!C19 -> 9.5 | C20: ='Uke 18'!C38 -> 18 | D20: ='Uke 18'!C57 -> 19.5 | E20: =SUM(B20:D20) -> 47 | G20: =(B20+C20+D20)/3 -> 15.666667 | I20: INGA rapport | J20: 30.04
A21: 19 | B21: ='Uke 19'!C19 -> 26 | C21: ='Uke 19'!C38 -> 24 | D21: ='Uke 19'!C57 -> 26 | E21: =SUM(B21:D21) -> 76 | G21: =(B21+C21+D21)/3 -> 25.333333
A22: 20 | B22: ='Uke 20'!C19 -> 47.5 | C22: ='Uke 20'!C38 -> 39 | D22: ='Uke 20'!C57 -> 39.5 | E22: =SUM(B22:D22) -> 126 | G22: =(B22+C22+D22)/3 -> 42 | I22: 20.05, uke 21 | J22: rapport innlevering
A23: Sum antall timer pr person/totalt | B23: =SUM(B4:B22) -> 322 | C23: =SUM(C4:C22) -> 339.3 | D23: =SUM(D4:D22) -> 397.5 | E23: =SUM(E4:E22) -> 1058.8 | G23: =G9+G10+G11+G12+G14+G15+G13+G16+G18+G17+G19+G20+G21+G22+G8+G7+G6+G5+G4 -> 352.93333 | H23: ca. gj per person

Sheet Uke 2
A1: Timelister med statusrapporter | F1: Ukerapport
F2: Dette skal være en kort beskrivelse av hva hver enkelt i gruppa (med navn) har arbeidet med i siste periode - og også en overordnet vurdering.
A3: Timeliste | C3: Andreas
A4: Aktivitet | B4: Kategori | C4: Antall timer
A5: Lesing | C5: 8
A6: møter | C6: 2
A19: Ukesum uke 2 | C19: =SUM(C5:C18) -> 10
A22: Timeliste | C22: Brage
A23: Aktivitet | B23: Kategori | C23: Antall timer
A24: Første møte med bachelorgruppa | B24: Møte | C24: 2
A25: Oppstartmøte med veilederne og bachelorgruppa | B25: Møte | C25: 1
A26: Artikellesing og info sammling | B26: Selvstudie | C26: 4
A27: Møte 09.01 med gruppen | B27: Møte | C27: 2
A38: =A19 -> Ukesum uke 2 | C38: =SUM(C24:C37) -> 9
A41: Timeliste | C41: Mateusz
A42: Aktivitet | B42: Kategori | C42: Antall timer
A43: Første møte med bachelorgruppa | B43: Møte | C43: 2
A44: Oppstartmøte med veilederne og bachelorgruppa | B44: Møte | C44: 1
A45: Artikkel lesning, lagde notater, Boka om maskinlæring | B45: Selvstudie | C45: =2+2+1.5+1 -> 6.5
A46: Andre møte den 09.01 | B46: Møte | C46: 2
A57: =A19 -> Ukesum uke 2 | C57: =SUM(C43:C56) -> 11.5

Sheet Uke 3
A1: Timelister med statusrapporter | F1: Ukerapport
F2: Dette skal være en kort beskrivelse av hva hver enkelt i gruppa (med navn) har arbeidet med i siste periode - og også en overordnet vurdering.
A3: Timeliste | C3: Andreas
A4: Aktivitet | B4: Kategori | C4: Antall timer
A5: 12.01 gruppe møte | B5: møte | C5: 1
A6: Selvstendig lesing 12.01 | C6: 4
A7: Selvstendig lesing 13.01 | C7: 4
A8: Selvstendig lesing kamera 14.01 | C8: 4
A19: Ukesum uke 3 | C19: =SUM(C5:C18) -> 13
A22: Timeliste | C22: Brage
A23: Aktivitet | B23: Kategori | C23: Antall timer
A24: Møte 12.01 med gruppa | B24: Møte | C24: 1
A25: Selvstending lesing | B25: Selvstudie | C25: 1
A26: Møte 14.01 med gruppe og veiledere | B26: Møte | C26: 1
A27: Lesing og testing av Qt for pyhton | B27: Selvstudie | C27: 1
A28: Artikel lesing og Python baserte ui | B28: Selvstudie | C28: 6
A38: =A19 -> Ukesum uke 3 | C38: =SUM(C24:C37) -> 10
A41: Timeliste | C41: Mateusz
A42: Aktivitet | B42: Kategori | C42: Antall timer
A43: 12.01 møte med gruppe | B43: Møte | C43: 1
A44: Artikkel lesing, notater etc | B44: Selvstudie | C44: 1
A45: MFCC, LPCC | B45: Koding | C45: =2.5+2+1 -> 5.5
A46: 14.01 møte med veileder | B46: Møte | C46: 1
A47: STM32 koding: - PDM2PCM | B47: Koding | C47: =3+4 -> 7
A57: =A19 -> Ukesum uke 3 | C57: =SUM(C43:C56) -> 15.5

Sheet Uke 4
A1: Timelister med statusrapporter | F1: Ukerapport
F2: Dette skal være en kort beskrivelse av hva hver enkelt i gruppa (med navn) har arbeidet med i siste periode - og også en overordnet vurdering.
A3: Timeliste | C3: Andreas
A4: Aktivitet | B4: Kategori | C4: Antall timer
A5: 20.01 Møte med veileder | B5: Møte | C5: 0.5
A6: 21.01 felles skriving av forprosjektet | B6: Gruppearbeid | C6: 2
A7: 19.01 Selvstendig lesing | B7: Lesing | C7: 4
A8: 20.01 Skriving av forprosjekt | B8: Forprosjekt | C8: 1.5
A9: 21.01 Selvstending skriving | B9: Forprosjekt | C9: 2.5
A10: 22.01 forprosjekt skriving | B10: Forprosjekt | C10: 3
A11: 23.01 Selvstending lesing | B11: Planlegging av Kameratracking oppsett | C11: 4
A19: Ukesum uke 4 | C19: =SUM(C5:C18) -> 17.5
A22: Timeliste | C22: Brage
A23: Aktivitet | B23: Kategori | C23: Antall timer
A24: Møte med veileder 20.01 | B24: Møte | C24: 0.5
A25: Forproskjet møte/arbeid med gruppa 21.01 | B25: Gruppearbeid | C25: 1.5
A26: Forproskjet arbeid med gruppa 22.01 | B26: Gruppearbeid | C26: 3
A27: Selvstendig Lesing og testing av Wireframe tool 21.01 | B27: Selvstudie | C27: 2
A28: Basic Wireframe draft 1 21.01 - 22.01 | C28: 1
A29: Dataset søk 22.01 | C29: 0.5
A30: Forproskjet arbeid med gruppa 22.01 | C30: 3
A31: Lesing om Baclherskriving 23.01-25.01 | B31: Selvstudie | C31: 3
A32: Lesing om Maskinlærings metoder23.01-25.01 | B32: Selvstudie | C32: 4
A33: Lesing og testing av Python basert GUI | B33: Selvstudie | C33: 4.5
A38: =A19 -> Ukesum uke 4 | C38: =SUM(C24:C37) -> 23
A41: Timeliste | C41: Mateusz
A42: Aktivitet | B42: Kategori | C42: Antall timer
A43: STM32 koding: - PDM2PCM, UART den 19.01 | B43: Koding | C43: 5
A44: 20.01 felles skriving av forprosjektet | B44: Gruppearbeid | C44: 1.5
A45: 20.01 Møte med veileder | B45: Møte | C45: 0.5
A46: 21.01 felles skriving av forprosjektet | B46: Gruppearbeid | C46: 3
A47: 22.01 felles skriving av forprosjektet | B47: Gruppearbeid | C47: 3
A48: 22.01 STM32 koding, usart funker, men uten klokke | B48: Koding | C48: 4.5
A49: 24.01 STM32 koding og feilsøking (fikset klokke frekvens til mikrofonene, har PD signal igjen ) | B49: Koding | C49: 5
A50: 25.01 STM32 koding og feilsøking (Mikrofoner sender lyd, lyden konverteres fra PDM til PCM, men signalet mottat av py skripten er alt for støyende) | B50: Koding | C50: 2
A57: =A19 -> Ukesum uke 4 | C57: =SUM(C43:C56) -> 24.5

Sheet Uke 5
A1: Timelister med statusrapporter | F1: Ukerapport
F2: Dette skal være en kort beskrivelse av hva hver enkelt i gruppa (med navn) har arbeidet med i siste periode - og også en overordnet vurdering.
A3: Timeliste | C3: Andreas
A4: Aktivitet | B4: Kategori | C4: Antall timer
A5: 26.01 Møte i gruppa | C5: 1
A6: 26.01 Oppsett raspberry pi og Pan/Tilt kamera løsning | C6: 4 | F6: Lånt Raspberry Pi 4B +2 servo motorer. Lånte et kamera til Raspberry som ikke funket.
A7: 28.01 Sett på 3D design av kamera | B7: Selvstendig jobbing | C7: 5
A8: 29.01 Sett på komponenter til utstyrsliste + møte | C8: 5 | F8: Sett nærmere på motordrivere + batteri.
A9: 30.01 Utstyrslise og møtereferat | C9: 6
A19: Ukesum uke 5 | C19: =SUM(C5:C18) -> 21
A22: Timeliste | C22: Brage
A23: Aktivitet | B23: Kategori | C23: Antall timer | F23: Leste opp på Rasperipi som webserver og diskuterte planer fra veileder møtet
A24: 26.01 Møte i gruppa | B24: Møte | C24: 1 | F24: Jobbet mindre en planlagt pga sykdom i sluten av uken
A25: 26.01 - 27.01 Lesing om masiknlæring metoder og data struktur | B25: SelvstendigLesing | C25: 2
A26: 26.01 Fikse python enviroment og lage GUI skjelett | B26: Selvstendig Arbeid | C26: 2
A27: 28.01 møte med gruppe om framdrifts raport | B27: Møte | C27: 1
A28: 29.01 møte med veileder | B28: Møte | C28: 1
A29: lesing om Rasperipi | C29: 5
A30: lesing om kart for webserver,api | C30: 3
A38: =A19 -> Ukesum uke 5 | C38: =SUM(C24:C37) -> 15
A41: Timeliste | C41: Mateusz | F41: Mateusz:
A42: Aktivitet | B42: Kategori | C42: Antall timer | F42: Jeg har endelig fått mikrofonene til å samle opp lyden,
A43: 26.01 gruppemøte | B43: Møte | C43: 2 | F43: Jeg har begynt å filtrere signalet med hanning/hamming og båndpass filteret
A44: 26.01 stm32 feilsøking og filtering av signalet samlet av mikrofonene | B44: Koding | C44: 2
A45: 28.01 Felles Fremdriftsrapport skriving | B45: Møte | C45: 1
A46: 28.01 Lesing om STM32 | B46: Selvstudie | C46: 1
A47: 29.01 møte med veileder | B47: Møte | C47: 1
A48: 29.01 Separasjon av signaler fra mikrofonene fra stm32 til py skript, gcc-phat implementasjon for å detektere retningen dronen kommer fra | B48: Koding/lesing | C48: 3
A49: 30.01 GCC-Phat algoritme, lesing og implementasjon | B49: Koding/lesing | C49: 6
A50: 31.01 GCC-phat, må teste algorithme med større avstand mellom mikrofonene | B50: Koding | C50: 2
A57: =A19 -> Ukesum uke 5 | C57: =SUM(C43:C56) -> 18

Sheet Uke 6
A1: Timelister med statusrapporter | F1: Ukerapport
F2: Dette skal være en kort beskrivelse av hva hver enkelt i gruppa (med navn) har arbeidet med i siste periode - og også en overordnet vurdering.
A3: Timeliste | C3: Andreas
A4: Aktivitet | B4: Kategori | C4: Antall timer
A5: 02.02 Begynt med 3d design | C5: 6
A6: 03.02 Møtet med gruppa for utstyrsliste | C6: 2
A7: 03.02 3D design CAD forts. | C7: 1.5
A8: 04.02 3D design CAD forts. | C8: 5.5
A9: 06.02 3D design CAD forts | C9: 3
A19: Ukesum uke 6 | C19: =SUM(C5:C18) -> 18
A22: Timeliste | C22: Brage
A23: Aktivitet | B23: Kategori | C23: Antall timer
A24: 03.02 Møte med gruppa for utstyrsliste | C24: 2
A25: Lesing for forarbeid til webserver | C25: 6.5
A26: Koding for testing før rasperi | C26: 5
A27: html page koding | C27: 2
A38: =A19 -> Ukesum uke 6 | C38: =SUM(C24:C37) -> 15.5
A41: Timeliste | C41: Mateusz | F41: Mateusz
A42: Aktivitet | B42: Kategori | C42: Antall timer | F42: Har gått over fra UART til USB CDC
A43: 02.02 Gcc testing | B43: Kode | C43: 1.5 | F43: GCC funker
A44: 03.02 Møte med gruppa for utstyrsliste | B44: Møte | C44: 2
A45: 04.02 Testeing av mikrofoner og kommunikasjonen. Fant en feil med data mengde som overføres fra stm32 til pc | B45: Kode | C45: 4.5
A46: 05.02 Testing av gcc-phat med 2 mikrofoner. Kan bekrefte hvor lyden kommer fra | B46: Kode | C46: 3
A47: 07.02 Gcc arbeid, omskiriving av interpolering for gcc, implementasjon av USB CDC på stm32 | B47: Kode | C47: 3
A48: 08.02 GCC fungerer med 2 mics, Har implementert USB CDC på stm32 som også fungerer | B48: Kode | C48: 4
A57: =A19 -> Ukesum uke 6 | C57: =SUM(C43:C56) -> 18

Sheet Uke 7
A1: Timelister med statusrapporter | F1: Ukerapport
F2: Dette skal være en kort beskrivelse av hva hver enkelt i gruppa (med navn) har arbeidet med i siste periode - og også en overordnet vurdering.
A3: Timeliste | C3: Andreas
A4: Aktivitet | B4: Kategori | C4: Antall timer
A5: 10.02 Møte | C5: 0.5
A6: 11.02 3D design | C6: 5
A7: 12.02 møte med gruppen | C7: 1
A8: 12.02 møte med veileder | C8: 1
A9: 12.02 3d design forts | C9: 4
A10: 13.03 fortsettelse 3D design, + sett på kulelager | C10: 5.5
A19: Ukesum uke 7 | C19: =SUM(C5:C18) -> 17
A22: Timeliste | C22: Brage
A23: Aktivitet | B23: Kategori | C23: Antall timer
A24: 10.02 Møte med medveileder | B24: Møte | C24: 1
A25: 11.02 Lese om Docker for Rassperi Pi | B25: lessing | C25: 2
A26: 12.02 Gruppemøte | B26: Møte | C26: 2
A27: 13.02 lesing ,testing av docker desktop og lignende verktøy | B27: lesing og testing | C27: 3
A28: 14.02 Forarbeid for rasperipi | B28: koding og lesing | C28: 3
A29: 15.02 Lage basic Openstreatmap og docker webpage | B29: koding | C29: 8
A38: =A19 -> Ukesum uke 7 | C38: =SUM(C24:C37) -> 19
A41: Timeliste | C41: Mateusz
A42: Aktivitet | B42: Kategori | C42: Antall timer
A43: 09.02 Testing av GCC med 4 mikrofoner | B43: Kode/Testing | C43: 4
A44: 10.02 Testing av GCC, fant ut at alle mikrofonene sender ut signal på raising edge, må fikses før videre arbeid | B44: Kode/Testing | C44: 2
A45: 10.02 Veiledermøte | B45: Møte | C45: 0.5
A46: 11.02 Feilsøking av data fra stm32, funker nå, feilindeksering av verdier sendt til PDM_Filter. | B46: Kode/Testing | C46: 4
A47: 11.02 FlowChart + notater | B47: Tegning | C47: 2
A48: 12.02 Veiledermøte og gruppemøte | B48: Møte | C48: 3
A49: 13.02 GCC phat testing med 4 mikrofonene | B49: Kode/Testing | C49: 4
A50: 13.02 3D og printing | B50: 3D design | C50: 1
A51: 14.02 MFCC + GCC + Github opplastinger | B51: Kode/Administrativ | C51: 1.5
A52: 15.02 3D design av mikrofon stativer | B52: 3D design | C52: 4
A57: =A19 -> Ukesum uke 7 | C57: =SUM(C43:C56) -> 26

Sheet Uke 8
A1: Timelister med statusrapporter | F1: Ukerapport
F2: Dette skal være en kort beskrivelse av hva hver enkelt i gruppa (med navn) har arbeidet med i siste periode - og også en overordnet vurdering.
A3: Timeliste | C3: Andreas
A4: Aktivitet | B4: Kategori | C4: Antall timer
A5: 16.02 Lån av utstyr, 3d printing, og 3d design | C5: 6
A6: 18.02 3D printing og design | C6: 5
A7: 19.02 3D printing og design | C7: 5
A8: 20.02 3D printing | C8: 1
A9: 21.02 3D design | C9: 4
A19: Ukesum uke 8 | C19: =SUM(C5:C18) -> 21
A22: Timeliste | C22: Brage
A23: Aktivitet | B23: Kategori | C23: Antall timer
A25: 17.02 lesing om WCAG, ux lover | B25: lesing | C25: 2
A26: 17.02 pørvde og fikse simulert drone markering | B26: Koding/testing | C26: 3
A27: 18.02 gruppe møte | B27: møte | C27: 1
A28: 19.02 Fikset struktur i webapp, og fikset camera | B28: Koding | C28: 6
A29: 20.02 prepping og lesing for raspberrypi | B29: lesing | C29: 1
A30: 22.02 settupp av raspberrypi for webserver( skulle gjøre mer menn ahdde hervære problemb med personlig laptop) | B30: Koding/testing | C30: 2
A31: 22.02 sytling og trubleshoting av webserver code | C31: 5
A38: =A19 -> Ukesum uke 8 | C38: =SUM(C24:C37) -> 20
A41: Timeliste | C41: Mateusz
A42: Aktivitet | B42: Kategori | C42: Antall timer
A43: 16.02 3D printing + administrativ | B43: 3D printing/ Administrativ | C43: 3
A44: 16.02 GCC test - gir nå riktig fortegn avhenging av lyd retningen | B44: Koding/testing | C44: 1
A45: 18.02 Gruppemøte | B45: Møte | C45: 1
A46: 18.02 3D printing + administrativt arbeid | B46: 3D printing/ Administrativ | C46: 3
A47: 19.02 GCC TDOA to Angle | B47: Koding | C47: 4.5
A48: 20.02 Rapport skriving | B48: Rapport | C48: 2
A49: 20.02 GCC testing | B49: Koding/testing | C49: 2.5
A50: 21.02 Får tilfedig azimuth, muligens data fra mikrofonene er feil, mulig mics på samme kanal er avhengige av hverandre som ødeleger estimering av retningen :( | B50: Koding/testing | C50: 11
A51: 21.02 Fortsatte å feilsøke stm32, fant ut at problemet er feil stacking av bits av peripherial siden f446 har ikke ordentlig PDM protokol, istedet har den en free protokol , som bare hiver bits i nesten tilfeldig rekkefølge så jeg får ikke nøyaktig en bit per mic (|mic1 bit| mic2 bit| mic1 bit| ... ) Har besluttet at jeg må kjøpe STM32H743ZI, som har en integrert SAI PDM | B51: Koding/testing | C51: 8
A57: =A19 -> Ukesum uke 8 | C57: =SUM(C43:C56) -> 36

Sheet Uke 9
A1: Timelister med statusrapporter | F1: Ukerapport
F2: Dette skal være en kort beskrivelse av hva hver enkelt i gruppa (med navn) har arbeidet med i siste periode - og også en overordnet vurdering.
A3: Timeliste | C3: Andreas
A4: Aktivitet | B4: Kategori | C4: Antall timer
A5: 23.02 3D design og print | C5: 5
A6: 25.02 3D design og print | C6: 5
A7: 26.02 3D design og Print | C7: 5
A8: 27.02 3D design og oppsett av RPI med AI hatt | C8: 5
A19: Ukesum uke 9 | C19: =SUM(C5:C18) -> 20
A22: Timeliste | C22: Brage
A23: Aktivitet | B23: Kategori | C23: Antall timer
A24: 23.02 GruppeMøte | B24: Møte | C24: 1
A25: 24.02 Raspberry Pi trubleshoting internet | C25: 2
A26: 25.02 Raspberry Pi trubleshoting internet | B26: pain | C26: 1
A27: 25.02 møte med veileder og mentor | B27: Møte | C27: 0.5
A28: 25.02 forarbeid/arbeid med dns og https | C28: 3
A29: 26.02 mer dns,https og ssl jobbing | B29: koding/lesing | C29: 6
A30: 27.02 prøve å få PI til og koble til net/vnc mer en en gang | C30: 4
A38: =A19 -> Ukesum uke 9 | C38: =SUM(C24:C37) -> 17.5
A41: Timeliste | C41: Mateusz
A42: Aktivitet | B42: Kategori | C42: Antall timer
A43: 23.02 GruppeMøte | B43: Møte | C43: 1
A44: 23.02 Kontroll av nye stm32 til bestilling | B44: Administrativ | C44: 1
A45: 25.02 Konversjon av stm32 prosjektet til den nye MCU-en | B45: Koding | C45: 2
A46: 25.02 Veiledermøte | B46: Møte | C46: 0.5
A47: 26.02 Konversjon av stm32 prosjektet til den nye MCU-en | B47: Koding | C47: 2
A48: 27.02 rapport skriving | B48: Rapport | C48: 2
A49: Jeg var syk mestparten av uka
A57: =A19 -> Ukesum uke 9 | C57: =SUM(C43:C56) -> 8.5

Sheet Uke 10
A1: Timelister med statusrapporter | F1: Ukerapport
F2: Dette skal være en kort beskrivelse av hva hver enkelt i gruppa (med navn) har arbeidet med i siste periode - og også en overordnet vurdering.
A3: Timeliste | C3: Andreas
A4: Aktivitet | B4: Kategori | C4: Antall timer
A5: 02.03 Kretsdesign | B5: PCB design | C5: 6
A6: 02.03 Assembly av kamera stativ | B6: 3D printing | C6: 1
A7: 04.03 Kretsdesign | B7: PCB design | C7: 6
A8: 5.03 test av motordriver | B8: Test | C8: 5
A9: 6.03 gruppemøte | B9: Møte | C9: 4
A19: Ukesum uke 10 | C19: =SUM(C5:C18) -> 22
A22: Timeliste | C22: Brage
A23: Aktivitet | B23: Kategori | C23: Antall timer
A24: 03.03 webserver/sertifikasjons programering | B24: kodding | C24: 3
A25: 04.03 gruppemøte | B25: møte | C25: 1
A26: 04.03 webserver/sertifikasjons programering | B26: kodding | C26: 8
A27: 05.03 webserver/sertifikasjons programering | B27: kodding | C27: 3
A28: 06.03 forarbeid go arbied til overføring og testing med PI | B28: lessing/koding | C28: 3.5
A29: 08.03 arbeid med Pi og trubelshoting | B29: kodding | C29: 4
A38: =A19 -> Ukesum uke 10 | C38: =SUM(C24:C37) -> 22.5
A41: Timeliste | C41: Mateusz
A42: Aktivitet | B42: Kategori | C42: Antall timer
A43: 03.03 3D printing | B43: 3D | C43: 1
A45: 04.03 gruppemøte | B45: Møte | C45: 1
A46: 04.03 PCB design | B46: PCB design | C46: 6
A47: 05.03 PCB design | B47: PCB design | C47: 3
A48: 06.03 PCB design | B48: PCB design | C48: 2
A49: 06.03 Møte | B49: Møte | C49: 1
A50: 07.03 PCB design | B50: PCB design | C50: 4.5
A51: 08.03 PCB design | B51: PCB design | C51: 7.5
A57: =A19 -> Ukesum uke 10 | C57: =SUM(C43:C56) -> 26

Sheet Uke 11
A1: Timelister med statusrapporter | F1: Ukerapport
F2: Dette skal være en kort beskrivelse av hva hver enkelt i gruppa (med navn) har arbeidet med i siste periode - og også en overordnet vurdering.
A3: Timeliste | C3: Andreas
A4: Aktivitet | B4: Kategori | C4: Antall timer
A5: 12.02 Møte med veileder | C5: 1
A6: 12.02 Jobbe med pitch | C6: 3
A7: 09.03 Gruppe møte | C7: 1.5
A8: 11.02 gruppemøte | C8: 1
A19: Ukesum uke 11 | C19: =SUM(C5:C18) -> 6.5
A22: Timeliste | C22: Brage
A23: Aktivitet | B23: Kategori | C23: Antall timer
A24: 09.03 gruppe møte | B24: Møte | C24: 1.5
A25: 09.03 oppset av tensorflow envriement og ML koding | B25: Koding | C25: 4
A26: 10.03 Ml Cnn koding | B26: Koding | C26: 6
A27: 11.03 gruppe møte | B27: Møte | C27: 2
A28: 11.03 møtereferat for 25.02 omskriving | B28: Administrativ | C28: 1
A29: 11.03 ML cnn koding | B29: Koding | C29: 4
A30: 12.03 Veiledermøte | B30: Møte | C30: 1
A31: 12.03 Portforwarding lessing | B31: lessing | C31: 1
A38: =A19 -> Ukesum uke 11 | C38: =SUM(C24:C37) -> 20.5
A41: Timeliste | C41: Mateusz
A42: Aktivitet | B42: Kategori | C42: Antall timer
A43: 09.03 Gruppemøte | B43: Møte | C43: 1
A44: 09.03 PCB design | B44: PCB Design | C44: 3
A45: 09.03 3D design | B45: 3D Design | C45: 1
A46: 10.03 PCB design | B46: PCB Design | C46: 0.5
A47: 11.03 Gruppe møte | B47: Møte | C47: 2
A48: 11.03 Bestilling av PCB og tilhørende komponenter | B48: Administrativ | C48: 1
A49: 11.03 3D design | B49: 3D Design | C49: 1
A50: 12.03 Veiledermøte | B50: Møte | C50: 1
A51: 12.03 Konversjon av algoritmer til moduler som skal fungere som et helt program | B51: Koding | C51: 5
A52: 13.03 Konversjon av algoritmer til moduler som skal fungere som et helt program | B52: Koding | C52: 3.5
A53: 14.03 Konversjon av algoritmer til moduler som skal fungere som et helt program | B53: Koding | C53: 2
A57: =A19 -> Ukesum uke 11 | C57: =SUM(C43:C56) -> 21

Sheet Uke 12
A1: Timelister med statusrapporter | F1: Ukerapport
F2: Dette skal være en kort beskrivelse av hva hver enkelt i gruppa (med navn) har arbeidet med i siste periode - og også en overordnet vurdering.
A3: Timeliste | C3: Andreas
A4: Aktivitet | B4: Kategori | C4: Antall timer
A5: 16.03 Pitch + jobbing med RPI | C5: 5
A6: 17.03 Jobbing med RPI | C6: 6
A7: 18.03 Mer jobbing med RPI | C7: 6
A8: 22.03 Jobbing med motor driver | C8: 4
A19: Ukesum uke 12 | C19: =SUM(C5:C18) -> 21
A22: Timeliste | C22: Brage
A23: Aktivitet | B23: Kategori | C23: Antall timer
A24: 16.03 møte før Bachelor presentasjoner | B24: møte | C24: 1
A25: 16.03 Bachelor presentasjoner | B25: Presentasjon | C25: 2
A26: 16.03 ML koding | B26: koding | C26: 3
A27: 17.03 portforwarding lesing og testing | B27: lessing | C27: 4
A28: 18.03 ML koding | B28: koding | C28: 3
A29: 19.03 ML koding | B29: koding | C29: 5
A30: 20.03 ML koding | B30: koding | C30: 1.5
A38: =A19 -> Ukesum uke 12 | C38: =SUM(C24:C37) -> 19.5
A41: Timeliste | C41: Mateusz
A42: Aktivitet | B42: Kategori | C42: Antall timer
A43: 16.03 Bachelor presentasjoner | B43: Presentasjon | C43: 2
A44: 16.03 Konversjon av algoritmer til moduler som skal fungere som et helt program | B44: Koding | C44: 1.5
A45: 18.03 Konversjon av algoritmer til moduler som skal fungere som et helt program | B45: Koding | C45: 1.5
A46: 19.03 Konversjon av algoritmer til moduler som skal fungere som et helt program | B46: Koding | C46: 4
A47: 20.03 Konversjon av koden | B47: Koding | C47: 2.5
A48: 20.03 Rapport skriving | B48: Rapport | C48: 2
A49: 21.03 Rapport skriving | B49: Rapport | C49: 4.5
A57: =A19 -> Ukesum uke 12 | C57: =SUM(C43:C56) -> 18

Sheet Uke 13
A1: Timelister med statusrapporter | F1: Ukerapport
F2: Dette skal være en kort beskrivelse av hva hver enkelt i gruppa (med navn) har arbeidet med i siste periode - og også en overordnet vurdering.
A3: Timeliste | C3: Andreas
A4: Aktivitet | B4: Kategori | C4: Antall timer
A5: 23.03 Jobbing med | C5: 6
A6: 24.03 Jobbing med | C6: 6
A7: 26.03 Møte med veileder | C7: 1
A8: 26.03 Jobbing | C8: 3
A19: Ukesum uke 13 | C19: =SUM(C5:C18) -> 16
A22: Timeliste | C22: Brage
A23: Aktivitet | B23: Kategori | C23: Antall timer
A24: 23.03 gruppemøte | B24: møte | C24: 1
A25: 23.03 Cnn ml koding | B25: koding | C25: 3
A26: 24.03 Cnn ml koding | B26: koding | C26: 4.5
A27: 24.03 lodding av pcb | B27: lodding | C27: 2
A28: 25.03 Cnn ml koding | B28: koding | C28: 5
A29: 26.03 cnn testinging koding med online data | B29: koding og testing | C29: 3.5
A30: 26.03 Testing og feilsøking av PCB | B30: PCB | C30: 2
A31: 27.03 Veileder møte | B31: møte | C31: 0.8
A32: 27.03 Omskriving av møtereferat | B32: Administrativ | C32: 1.5
A38: =A19 -> Ukesum uke 13 | C38: =SUM(C24:C37) -> 23.3
A41: Timeliste | C41: Mateusz
A42: Aktivitet | B42: Kategori | C42: Antall timer
A43: 23.03 Gruppemøte | B43: Møte | C43: 0.5
A44: 23.03 Rapport skriving | B44: Rapport | C44: 2
A45: 24.03 feilsøking og lodding av PCB | B45: PCB | C45: 5
A46: 25.03 Feilsøking av steppermotoren - DONE | B46: PCB | C46: 6.5
A47: 26.03 Testing og feilsøking av PCB | B47: PCB | C47: 7
A48: 26/27.03 Redesign av PCB | B48: PCB | C48: 3
A49: 27.03 Redesign av PCB | B49: PCB | C49: 2
A50: 27.03 Veileder møte | B50: PCB | C50: 0.5
A51: 27.03 Bestillinger | B51: Administrativ | C51: 0.5
A52: 29.03 STM32 Testing av SAI og konversjon til I2C, SPI | B52: Koding | C52: 1.5
A57: =A19 -> Ukesum uke 13 | C57: =SUM(C43:C56) -> 28.5

Sheet Uke 14
A1: Timelister med statusrapporter | F1: Ukerapport
F2: Dette skal være en kort beskrivelse av hva hver enkelt i gruppa (med navn) har arbeidet med i siste periode - og også en overordnet vurdering.
A3: Timeliste | C3: Andreas
A4: Aktivitet | B4: Kategori | C4: Antall timer
A19: Ukesum uke 14 | C19: =SUM(C5:C18) -> 0
A22: Timeliste | C22: "Person nr 2"
A23: Aktivitet | B23: Kategori | C23: Antall timer
A38: =A19 -> Ukesum uke 14 | C38: =SUM(C24:C37) -> 0
A41: Timeliste | C41: Mateusz
A42: Aktivitet | B42: Kategori | C42: Antall timer
A43: 30.03 STM32 feilsøking, ser ut som det funker nå, men må teste det med GCC | B43: Koding | C43: 9
A57: =A19 -> Ukesum uke 14 | C57: =SUM(C43:C56) -> 9

Sheet Uke 15
A1: Timelister med statusrapporter | F1: Ukerapport
F2: Dette skal være en kort beskrivelse av hva hver enkelt i gruppa (med navn) har arbeidet med i siste periode - og også en overordnet vurdering.
A3: Timeliste | C3: Andreas
A4: Aktivitet | B4: Kategori | C4: Antall timer
A5: 10.04 Møte med veileder | C5: 0.5
A19: Ukesum uke 15 | C19: =SUM(C5:C18) -> 0.5
A22: Timeliste | C22: "Person nr 2"
A23: Aktivitet | B23: Kategori | C23: Antall timer
A24: 08.04 teori skriving planleging | C24: 1.5
A25: 10.04 Veildermøte | B25: møte | C25: 1
A38: =A19 -> Ukesum uke 15 | C38: =SUM(C24:C37) -> 2.5
A41: Timeliste | C41: Mateusz
A42: Aktivitet | B42: Kategori | C42: Antall timer
A43: 10.04 Veildermøte | B43: Møte | C43: 1
A57: =A19 -> Ukesum uke 15 | C57: =SUM(C43:C56) -> 1

Sheet Uke 16
A1: Timelister med statusrapporter | F1: Ukerapport
F2: Dette skal være en kort beskrivelse av hva hver enkelt i gruppa (med navn) har arbeidet med i siste periode - og også en overordnet vurdering.
A3: Timeliste | C3: Andreas
A4: Aktivitet | B4: Kategori | C4: Antall timer
A5: 16.04 gruppemøte | C5: 1
A6: 17.04 Lodding av PCB | C6: 4.5
A7: 19.04 Lodding + test av PCB | C7: 2.5
A19: Ukesum uke 16 | C19: =SUM(C5:C18) -> 8
A22: Timeliste | C22: Brage
A23: Aktivitet | B23: Kategori | C23: Antall timer
A24: 13.04 omskriving av 10.04 møtereferat | C24: 2
A25: 14.04 innhenting av ny data til testing og trening | C25: 2
A26: 15.04 preping av ny data og endring av trening kode | B26: koding | C26: 5
A27: 16.04 gruppemøte | B27: møte | C27: 1
A28: 17.04 Ml koding av ny model | B28: koding | C28: 6
A29: 18.04 ml koding av ny model og testing med "ny" data | B29: koding | C29: 3
A38: =A19 -> Ukesum uke 16 | C38: =SUM(C24:C37) -> 19
A41: Timeliste | C41: Mateusz
A42: Aktivitet | B42: Kategori | C42: Antall timer
A43: 16.04 gruppemøte | B43: møte | C43: 1
A44: 17.04 GCC feilsøking | B44: koding | C44: 5
A45: 17.04 PCB lodding og testing | B45: testing | C45: 3
A46: 18.04 STM32 feilsøking | B46: koding | C46: 10
A47: 19.04 STM32 feilsøking | B47: koding | C47: =2+7 -> 9
A57: =A19 -> Ukesum uke 16 | C57: =SUM(C43:C56) -> 28

Sheet Uke 17
A1: Timelister med statusrapporter | F1: Ukerapport
F2: Dette skal være en kort beskrivelse av hva hver enkelt i gruppa (med navn) har arbeidet med i siste periode - og også en overordnet vurdering.
A3: Timeliste | C3: Andreas
A4: Aktivitet | B4: Kategori | C4: Antall timer
A5: 20.04 gruppemøte | C5: 1
A6: 20.04 Koding med h.265 enkoding i fokus | C6: 4
A7: 21.04 Enkoding + YOLO trening | C7: 3.5
A8: 22.04 Modellering av systemet | C8: 4
A9: 24.04 MQTT mellom RPI og Arduino + 3D print | C9: 5
A10: 25.04 3D design og lodding | C10: 6
A11: 26.04 Mer lodding og feilsøking av kretskort | C11: 4
A19: Ukesum uke 17 | C19: =SUM(C5:C18) -> 27.5
A22: Timeliste | C22: Brage
A23: Aktivitet | B23: Kategori | C23: Antall timer
A24: 20.04 gruppemøte | B24: møte | C24: 1
A25: 20.04 ml koding for lagring av ml modeler | B25: koding | C25: 1
A26: 20.04 pcb lodding | B26: lodding | C26: 5
A27: 21.04 ml standarisering og preping for main | B27: koding | C27: 3
A28: 21.04 metoder lesing og skriving | B28: rapport | C28: 2.5
A29: 22.04 lesing av rapport skriving metoder | B29: rapport | C29: 2
A30: 23.04 selvstendig testing | B30: testing | C30: 1
A31: 23.04 ml testing | B31: testing | C31: 3
A32: 25.04 Ml testing | B32: testing | C32: 3.5
A38: =A19 -> Ukesum uke 17 | C38: =SUM(C24:C37) -> 22
A41: Timeliste | C41: Mateusz
A42: Aktivitet | B42: Kategori | C42: Antall timer
A43: 20.04 gruppemøte | B43: møte | C43: 1
A44: 20.04 STM32 feilsøking | B44: koding | C44: 5
A45: 21.04 STM32 feilsøking | B45: koding | C45: 3
A46: 22.04 STM32 feilsøking, FUNKER!!!!!!!! | B46: koding | C46: 3
A47: 23.04 oppdatering av stm32 til å bruke 4 mikrofoner | B47: koding | C47: 1.5
A48: 23.04 testing av ml | B48: testing | C48: 1.5
A49: 25.04 testing av DOA, funker | B49: testing | C49: 3
A50: 26.04 testing av pcb | B50: testing | C50: 2
A51: 26.04 Rapport skriving | B51: rapport | C51: 3
A57: =A19 -> Ukesum uke 17 | C57: =SUM(C43:C56) -> 23

Sheet Uke 18
A1: Timelister med statusrapporter | F1: Ukerapport
F2: Dette skal være en kort beskrivelse av hva hver enkelt i gruppa (med navn) har arbeidet med i siste periode - og også en overordnet vurdering.
A3: Timeliste | C3: Andreas
A4: Aktivitet | B4: Kategori | C4: Antall timer
A5: 27.03 gruppemøte | C5: 1
A6: 27.03 Feilsøking PCB | C6: 2
A7: 29.03 Veileder møte | C7: 0.5
A8: 29.3 Oppsett av kamera pipeline + trening av YOLO | C8: 6
A19: Ukesum uke 18 | C19: =SUM(C5:C18) -> 9.5
A22: Timeliste | C22: "Person nr 2"
A23: Aktivitet | B23: Kategori | C23: Antall timer
A24: 27.04 Gruppemøte | B24: møte | C24: 1
A25: 27.04 Rapport skriving | B25: skriving | C25: 1.5
A26: 28.04 rapport skriving | B26: skriving | C26: 1
A27: 29.04 Rapport skriving | B27: skriving | C27: 2
A28: 30.04 socket programering(webserver) | B28: coding | C28: 3
A29: 02.05 retnigs estimering testing | B29: testing | C29: 3.5
A30: 02.05 socket programering | B30: coding | C30: 2
A31: 03.05 ml testing | B31: testing | C31: 3
A32: 03.05 testing og lesing med "ødelagt" rasberry | B32: testing | C32: 1
A38: =A19 -> Ukesum uke 18 | C38: =SUM(C24:C37) -> 18
A41: Timeliste | C41: Mateusz
A42: Aktivitet | B42: Kategori | C42: Antall timer
A43: 27.04 Gruppemøte | B43: møte | C43: 1
A44: 27.04 Rapport skriving | B44: rapport | C44: 2
A45: 29.04 Rapport skriving | B45: rapport | C45: 1
A46: 30.04 Rapport skriving | B46: rapport | C46: 2
A47: 01.05 Rapport skriving | B47: rapport | C47: 4
A48: 02.05 System testing | B48: testing | C48: 5
A49: 02.05 Rapport testing | B49: rapport | C49: 1
A50: 03.05 Rapport skriving | B50: rapport | C50: 1.5
A51: 03.05 System testing | B51: testing | C51: 2
A57: =A19 -> Ukesum uke 18 | C57: =SUM(C43:C56) -> 19.5

Sheet Uke 19
A1: Timelister med statusrapporter | F1: Ukerapport
F2: Dette skal være en kort beskrivelse av hva hver enkelt i gruppa (med navn) har arbeidet med i siste periode - og også en overordnet vurdering.
A3: Timeliste | C3: Andreas
A4: Aktivitet | B4: Kategori | C4: Antall timer
A5: 07.05 Feilsøking og testing av PCB | C5: 5
A6: 07.05 Training and testing YOLO model | C6: 4
A7: 08.05 møte | C7: 1
A8: 08.05 Rapport skriving + YOLO trening | C8: 5
A9: 09.05 Rapport skriving + YOLO trening | C9: 4
A10: 10.05 rapport skriving | C10: 3
A11: 10.05 Overføre YOLO modell til RPI | C11: 4
A19: Ukesum uke 19 | C19: =SUM(C5:C18) -> 26
A22: Timeliste | C22: "Person nr 2"
A23: Aktivitet | B23: Kategori | C23: Antall timer
A24: 04.05 ml testing of trenig med live data | B24: testing | C24: 5
A25: 05.05 ml testing | B25: testing | C25: 2
A26: 05.05 Rapport skriving | B26: skriving | C26: 2
A27: 06.05 Rapport skriving | B27: skriving | C27: 3
A28: 07.05 ml testing | B28: testing | C28: 3
A29: 08.05 ml testing | B29: coding | C29: 2
A30: 09.05 Rapport skriving | B30: skriving | C30: 4
A31: 10.05 rapport skriving | B31: skriving | C31: 3
A38: =A19 -> Ukesum uke 19 | C38: =SUM(C24:C37) -> 24
A41: Timeliste | C41: Mateusz
A42: Aktivitet | B42: Kategori | C42: Antall timer
A43: 04.05 System testing med live drone | B43: testing | C43: 2
A44: 04.05 Rapport skriving | B44: rapport | C44: 2
A45: 05.05 Rapport skriving | B45: rapport | C45: 3.5
A46: 06.05 Rapport skriving | B46: rapport | C46: 3
A47: 07.05 Rapport skriving | B47: rapport | C47: 3
A48: 08.05 Rapport skriving | B48: rapport | C48: 3
A49: 09.05 Rapport skriving | B49: rapport | C49: 4
A50: 10.05 Rapport skriving | B50: rapport | C50: 4
A51: 08.05 Møte | B51: Møte | C51: 1.5
A57: =A19 -> Ukesum uke 19 | C57: =SUM(C43:C56) -> 26

Sheet Uke 20
A1: Timelister med statusrapporter | F1: Ukerapport
F2: Dette skal være en kort beskrivelse av hva hver enkelt i gruppa (med navn) har arbeidet med i siste periode - og også en overordnet vurdering.
A3: Timeliste | C3: Andreas
A4: Aktivitet | B4: Kategori | C4: Antall timer
A5: 11.05 gruppemøte | C5: 1
A6: 11.05 Overført YOLO model til RPI | C6: 2
A7: 11.05 Rapport skriving | C7: 1
A8: 12.05 gruppemøte | C8: 1
A9: 12.05 poster | C9: 4
A10: 12.05 Ferdigstillt kamera pipeline på RPI med objekt gjenkjenning | C10: 2
A11: 13.05 Feilsøking kretskort, Forberede tester, 3D printing | C11: 4
A12: 13.05 Teste HAILO chip på rpi | C12: 3
A13: 14.05 Testing av DOA | C13: 2.5
A14: 14.05 Bearbeiding av data | C14: 5
A15: 15.05 Skriving på diskusjonsdelen | C15: 5
A16: 16.05 Opplasting av kode + skriving på rapport | C16: 5
... A18: 19.05 Rapport skriving + video presentasjon | C18: 10
A19: Ukesum uke 20 | C19: =SUM(C5:C18) -> 47.5
A22: Timeliste | C22: Brage
A23: Aktivitet | B23: Kategori | C23: Antall timer
A24: 11.05 gruppemøte | B24: møte | C24: 1
A25: 11.05 Rapport skriving | B25: skriving | C25: 2
A26: 11.05 gui update med vinkel | B26: kode | C26: 3
A27: 12.05 veileder møte | B27: møte | C27: 1
A28: 12.05 gruppe møte | B28: møte | C28: 1
A29: 12.05 Rapport skriving | B29: skriving | C29: 1.5
A30: 12.05 GUI koding, unit test og camera | B30: coding | C30: 3.5
A31: 13.05 Rapport skriving | B31: skriving | C31: 3.5
A32: 13.05-14.05 gui koding, camra display | B32: coding | C32: 2
A33: 13.05-14.05 python envirement for test | C33: 2.5
A34: 14.05 live test med drone, og data oppload fra test | C34: 3
A35: 15.04-17.04 rapport skriving | C35: 6
A36: 18.05 Rapport skriving + møte + admin tasks | C36: 5
A37: 19.05 Rapport + video presentasjon + møte | C37: 4
A38: =A19 -> Ukesum uke 20 | C38: =SUM(C24:C37) -> 39
A41: Timeliste | C41: Mateusz
A42: Aktivitet | B42: Kategori | C42: Antall timer
A43: 11.05 gruppemøte | B43: møte | C43: 1
A44: 11.05 Rapport skriving | B44: rapport | C44: 2
A45: 12.05 Div meetings | B45: møte | C45: 2
...
